<?xml version="1.0" ?>
<!-- =================================================================================== -->
<!-- |    This document was autogenerated by xacro from gp25_macro.xacro               | -->
<!-- |    EDITING THIS FILE BY HAND IS NOT RECOMMENDED                                 | -->
<!-- =================================================================================== -->
<robot name="motoman_gp25" xmlns:xacro="http://ros.org/wiki/xacro">

    <!-- link list -->
    <link name="base_link">
        <visual>
            <geometry>
                <mesh filename="package://motoman_gp25_support/meshes/visual/base_link.stl"/>
            </geometry>
            <material name="blue">
                <color rgba="0 0 1 1"/>
      	    </material>
        </visual>
        <collision>
            <geometry>
                <mesh filename="package://motoman_gp25_support/meshes/collision/base_link.stl"/>
            </geometry>
	    <material name="blue">
                <color rgba="0 0 1 1"/>
      	    </material>
        </collision>
    </link>
    <link name="link_1_s">
        <visual>
            <geometry>
                <mesh filename="package://motoman_gp25_support/meshes/visual/link_1_s.stl"/>
            </geometry>
            <material name="blue">
                <color rgba="0 0 1 1"/>
      	    </material>
        </visual>
        <collision>
            <geometry>
                <mesh filename="package://motoman_gp25_support/meshes/collision/link_1_s.stl"/>
            </geometry>
	    <material name="blue">
                <color rgba="0 0 1 1"/>
      	    </material>
        </collision>
    </link>
    <link name="link_2_l">
        <visual>
            <geometry>
                <mesh filename="package://motoman_gp25_support/meshes/visual/link_2_l.stl"/>
            </geometry>
            <material name="blue">
                <color rgba="0 0 1 1"/>
      	    </material>
        </visual>
        <collision>
            <geometry>
                <mesh filename="package://motoman_gp25_support/meshes/collision/link_2_l.stl"/>
            </geometry>
	    <material name="blue">
                <color rgba="0 0 1 1"/>
      	    </material>
        </collision>
    </link>
    <link name="link_3_u">
        <visual>
            <geometry>
                <mesh filename="package://motoman_gp25_support/meshes/visual/link_3_u.stl"/>
            </geometry>
            <material name="blue">
                <color rgba="0 0 1 1"/>
      	    </material>
        </visual>
        <collision>
            <geometry>
                <mesh filename="package://motoman_gp25_support/meshes/collision/link_3_u.stl"/>
            </geometry>
	    <material name="blue">
                <color rgba="0 0 1 1"/>
      	    </material>
        </collision>
    </link>
    <link name="link_4_r">
        <visual>
            <geometry>
                <mesh filename="package://motoman_gp25_support/meshes/visual/link_4_r.stl"/>
            </geometry>
            <material name="blue">
                <color rgba="0 0 1 1"/>
      	    </material>
        </visual>
        <collision>
            <geometry>
                <mesh filename="package://motoman_gp25_support/meshes/collision/link_4_r.stl"/>
            </geometry>
	    <material name="blue">
                <color rgba="0 0 1 1"/>
      	    </material>
        </collision>
    </link>
    <link name="link_5_b">
        <visual>
            <geometry>
                <mesh filename="package://motoman_gp25_support/meshes/visual/link_5_b.stl"/>
            </geometry>
            <material name="blue">
                <color rgba="0 0 1 1"/>
      	    </material>
        </visual>
        <collision>
            <geometry>
                <mesh filename="package://motoman_gp25_support/meshes/collision/link_5_b.stl"/>
            </geometry>
	    <material name="blue">
                <color rgba="0 0 1 1"/>
      	    </material>
        </collision>
    </link>
    <link name="link_6_t">
        <visual>
            <geometry>
                <mesh filename="package://motoman_gp25_support/meshes/visual/link_6_t.stl"/>
            </geometry>
            <material name="blue">
                <color rgba="0 0 1 1"/>
      	    </material>
        </visual>
        <collision>
            <geometry>
                <mesh filename="package://motoman_gp25_support/meshes/collision/link_6_t.stl"/>
            </geometry>
	    <material name="blue">
                <color rgba="0 0 1 1"/>
      	    </material>
        </collision>
    </link>
    <link name="tool0"/>
    <!-- end of link list -->

    <!-- joint list -->
    <joint name="joint_1_s" type="revolute">
        <parent link="base_link"/>
        <child link="link_1_s"/>
        <origin xyz="0 0 0.505" rpy="0 0 0" />
        <axis xyz="0 0 1" />
        <limit lower="-3.1415" upper="3.1415" effort="3087" velocity="3.66519"/>
    </joint>
    <joint name="joint_2_l" type="revolute">
        <parent link="link_1_s"/>
        <child link="link_2_l"/>
        <origin xyz="0.150 0 0" rpy="0 0 0" />
        <axis xyz="0 1 0" />
        <limit lower="-1.8326" upper="2.70526" effort="3087" velocity="3.66519"/>
    </joint>
    <joint name="joint_3_u" type="revolute">
        <parent link="link_2_l"/>
        <child link="link_3_u"/>
        <origin xyz="0 0 0.760" rpy="0 0 0" />
        <axis xyz="0 -1 0" />
        <limit lower="-1.50098" upper="2.79253" effort="926.1" velocity="4.62512"/>
    </joint>
    <joint name="joint_4_r" type="revolute">
        <parent link="link_3_u"/>
        <child link="link_4_r"/>
        <origin xyz="0 0 0.200" rpy="0 0 0" />
        <axis xyz="-1 0 0" />
        <limit lower="-3.49066" upper="3.49066" effort="88.2" velocity="7.33038"/>
    </joint>
    <joint name="joint_5_b" type="revolute">
        <parent link="link_4_r"/>
        <child link="link_5_b"/>
        <origin xyz="0.795 0 0" rpy="0 0 0" />
        <axis xyz="0 -1 0" />
        <limit lower="-2.70526" upper="2.61799" effort="70.56" velocity="7.33038"/>
    </joint>
    <joint name="joint_6_t" type="revolute">
        <parent link="link_5_b"/>
        <child link="link_6_t"/>
        <origin xyz="0 0 0" rpy="0 0 0" />
        <axis xyz="-1 0 0" />
        <limit lower="-7.94125" upper="7.94125" effort="50.31" velocity="15.4462"/>
    </joint>
    <joint name="joint_6_t-tool0" type="fixed">
        <origin xyz="0.100 0 0" rpy="3.1415926 -1.570796 0"/>
        <parent link="link_6_t"/>
        <child link="tool0"/>
    </joint>
    <!-- end of joint list -->

    <!-- ROS base_link to Robot Manufacturer World Coordinates transform -->
    <link name="base" />
    <joint name="base_link-base" type="fixed">
        <origin xyz="0 0 0.505" rpy="0 0 0"/>
        <parent link="base_link"/>
        <child link="base"/>
    </joint>
</robot>
